[2025-04-14T21:14:34.378+0000] {taskinstance.py:1157} INFO - Dependencies all met for dep_context=non-requeueable deps ti=<TaskInstance: dag_id_example.task_id_example2 scheduled__2023-11-26T02:15:06+00:00 [queued]>
[2025-04-14T21:14:34.400+0000] {taskinstance.py:1157} INFO - Dependencies all met for dep_context=requeueable deps ti=<TaskInstance: dag_id_example.task_id_example2 scheduled__2023-11-26T02:15:06+00:00 [queued]>
[2025-04-14T21:14:34.400+0000] {taskinstance.py:1359} INFO - Starting attempt 1 of 1
[2025-04-14T21:14:34.435+0000] {taskinstance.py:1380} INFO - Executing <Task(_PythonDecoratedOperator): task_id_example2> on 2023-11-26 02:15:06+00:00
[2025-04-14T21:14:34.449+0000] {standard_task_runner.py:57} INFO - Started process 2486 to run task
[2025-04-14T21:14:34.461+0000] {standard_task_runner.py:84} INFO - Running: ['***', 'tasks', 'run', 'dag_id_example', 'task_id_example2', 'scheduled__2023-11-26T02:15:06+00:00', '--job-id', '2298', '--raw', '--subdir', 'DAGS_FOLDER/example_Dag.py', '--cfg-path', '/tmp/tmpmsb5599m']
[2025-04-14T21:14:34.469+0000] {standard_task_runner.py:85} INFO - Job 2298: Subtask task_id_example2
[2025-04-14T21:14:34.694+0000] {task_command.py:415} INFO - Running <TaskInstance: dag_id_example.task_id_example2 scheduled__2023-11-26T02:15:06+00:00 [running]> on host 018b6bcbe942
[2025-04-14T21:14:35.020+0000] {local_task_job_runner.py:115} ERROR - Received SIGTERM. Terminating subprocesses
[2025-04-14T21:14:35.050+0000] {process_utils.py:131} INFO - Sending 15 to group 2486. PIDs of all processes in the group: [2486]
[2025-04-14T21:14:35.113+0000] {process_utils.py:86} INFO - Sending the signal 15 to group 2486
[2025-04-14T21:14:35.118+0000] {taskinstance.py:1630} ERROR - Received SIGTERM. Terminating subprocesses.
[2025-04-14T21:14:35.143+0000] {taskinstance.py:1935} ERROR - Task failed with exception
Traceback (most recent call last):
  File "/home/airflow/.local/lib/python3.8/site-packages/airflow/models/taskinstance.py", line 1516, in _run_raw_task
    self._execute_task_with_callbacks(context, test_mode, session=session)
  File "/home/airflow/.local/lib/python3.8/site-packages/airflow/models/taskinstance.py", line 1650, in _execute_task_with_callbacks
    RenderedTaskInstanceFields.delete_old_records(self.task_id, self.dag_id)
  File "/home/airflow/.local/lib/python3.8/site-packages/airflow/utils/session.py", line 77, in wrapper
    return func(*args, session=session, **kwargs)
  File "/home/airflow/.local/lib/python3.8/site-packages/airflow/models/renderedtifields.py", line 218, in delete_old_records
    cls._do_delete_old_records(
  File "/home/airflow/.local/lib/python3.8/site-packages/airflow/utils/retries.py", line 91, in wrapped_function
    for attempt in run_with_db_retries(max_retries=retries, logger=logger, **retry_kwargs):
  File "/home/airflow/.local/lib/python3.8/site-packages/tenacity/__init__.py", line 347, in __iter__
    do = self.iter(retry_state=retry_state)
  File "/home/airflow/.local/lib/python3.8/site-packages/tenacity/__init__.py", line 314, in iter
    return fut.result()
  File "/usr/local/lib/python3.8/concurrent/futures/_base.py", line 437, in result
    return self.__get_result()
  File "/usr/local/lib/python3.8/concurrent/futures/_base.py", line 389, in __get_result
    raise self._exception
  File "/home/airflow/.local/lib/python3.8/site-packages/airflow/utils/retries.py", line 100, in wrapped_function
    return func(*args, **kwargs)
  File "/home/airflow/.local/lib/python3.8/site-packages/airflow/models/renderedtifields.py", line 250, in _do_delete_old_records
    session.execute(stmt)
  File "/home/airflow/.local/lib/python3.8/site-packages/sqlalchemy/orm/session.py", line 1716, in execute
    conn = self._connection_for_bind(bind)
  File "/home/airflow/.local/lib/python3.8/site-packages/sqlalchemy/orm/session.py", line 1555, in _connection_for_bind
    return self._transaction._connection_for_bind(
  File "/home/airflow/.local/lib/python3.8/site-packages/sqlalchemy/orm/session.py", line 750, in _connection_for_bind
    conn = bind.connect()
  File "/home/airflow/.local/lib/python3.8/site-packages/sqlalchemy/future/engine.py", line 406, in connect
    return super(Engine, self).connect()
  File "/home/airflow/.local/lib/python3.8/site-packages/sqlalchemy/engine/base.py", line 3325, in connect
    return self._connection_cls(self, close_with_result=close_with_result)
  File "/home/airflow/.local/lib/python3.8/site-packages/sqlalchemy/engine/base.py", line 96, in __init__
    else engine.raw_connection()
  File "/home/airflow/.local/lib/python3.8/site-packages/sqlalchemy/engine/base.py", line 3404, in raw_connection
    return self._wrap_pool_connect(self.pool.connect, _connection)
  File "/home/airflow/.local/lib/python3.8/site-packages/sqlalchemy/engine/base.py", line 3371, in _wrap_pool_connect
    return fn()
  File "/home/airflow/.local/lib/python3.8/site-packages/sqlalchemy/pool/base.py", line 327, in connect
    return _ConnectionFairy._checkout(self)
  File "/home/airflow/.local/lib/python3.8/site-packages/sqlalchemy/pool/base.py", line 894, in _checkout
    fairy = _ConnectionRecord.checkout(pool)
  File "/home/airflow/.local/lib/python3.8/site-packages/sqlalchemy/pool/base.py", line 493, in checkout
    rec = pool._do_get()
  File "/home/airflow/.local/lib/python3.8/site-packages/sqlalchemy/pool/impl.py", line 256, in _do_get
    return self._create_connection()
  File "/home/airflow/.local/lib/python3.8/site-packages/sqlalchemy/pool/base.py", line 273, in _create_connection
    return _ConnectionRecord(self)
  File "/home/airflow/.local/lib/python3.8/site-packages/sqlalchemy/pool/base.py", line 388, in __init__
    self.__connect()
  File "/home/airflow/.local/lib/python3.8/site-packages/sqlalchemy/pool/base.py", line 691, in __connect
    pool.logger.debug("Error on connect(): %s", e)
  File "/home/airflow/.local/lib/python3.8/site-packages/sqlalchemy/util/langhelpers.py", line 70, in __exit__
    compat.raise_(
  File "/home/airflow/.local/lib/python3.8/site-packages/sqlalchemy/util/compat.py", line 211, in raise_
    raise exception
  File "/home/airflow/.local/lib/python3.8/site-packages/sqlalchemy/pool/base.py", line 686, in __connect
    self.dbapi_connection = connection = pool._invoke_creator(self)
  File "/home/airflow/.local/lib/python3.8/site-packages/sqlalchemy/engine/create.py", line 574, in connect
    return dialect.connect(*cargs, **cparams)
  File "/home/airflow/.local/lib/python3.8/site-packages/sqlalchemy/engine/default.py", line 598, in connect
    return self.dbapi.connect(*cargs, **cparams)
  File "/home/airflow/.local/lib/python3.8/site-packages/psycopg2/__init__.py", line 122, in connect
    conn = _connect(dsn, connection_factory=connection_factory, **kwasync)
  File "/home/airflow/.local/lib/python3.8/site-packages/airflow/models/taskinstance.py", line 1632, in signal_handler
    raise AirflowException("Task received SIGTERM signal")
airflow.exceptions.AirflowException: Task received SIGTERM signal
[2025-04-14T21:14:35.299+0000] {taskinstance.py:1398} INFO - Marking task as FAILED. dag_id=dag_id_example, task_id=task_id_example2, execution_date=20231126T021506, start_date=20250414T211434, end_date=20250414T211435
[2025-04-14T21:14:35.337+0000] {standard_task_runner.py:104} ERROR - Failed to execute job 2298 for task task_id_example2 (Task received SIGTERM signal; 2486)
[2025-04-14T21:14:35.383+0000] {process_utils.py:79} INFO - Process psutil.Process(pid=2486, status='terminated', exitcode=1, started='21:14:33') (2486) terminated with exit code 1
[2025-04-14T21:14:35.384+0000] {local_task_job_runner.py:228} INFO - Task exited with return code 143
[2025-04-14T21:14:37.316+0000] {taskinstance.py:2776} INFO - 0 downstream tasks scheduled from follow-on schedule check
[2025-04-14T21:14:37.587+0000] {local_task_job_runner.py:115} ERROR - Received SIGTERM. Terminating subprocesses
[2025-04-14T21:14:37.588+0000] {local_task_job_runner.py:228} INFO - Task exited with return code 143
