[2025-04-14T21:14:34.420+0000] {taskinstance.py:1157} INFO - Dependencies all met for dep_context=non-requeueable deps ti=<TaskInstance: dag_id_example.task_id_example3 scheduled__2023-11-26T02:15:06+00:00 [queued]>
[2025-04-14T21:14:34.455+0000] {taskinstance.py:1157} INFO - Dependencies all met for dep_context=requeueable deps ti=<TaskInstance: dag_id_example.task_id_example3 scheduled__2023-11-26T02:15:06+00:00 [queued]>
[2025-04-14T21:14:34.455+0000] {taskinstance.py:1359} INFO - Starting attempt 1 of 1
[2025-04-14T21:14:34.522+0000] {taskinstance.py:1380} INFO - Executing <Task(_PythonDecoratedOperator): task_id_example3> on 2023-11-26 02:15:06+00:00
[2025-04-14T21:14:34.558+0000] {standard_task_runner.py:57} INFO - Started process 2489 to run task
[2025-04-14T21:14:34.560+0000] {standard_task_runner.py:84} INFO - Running: ['***', 'tasks', 'run', 'dag_id_example', 'task_id_example3', 'scheduled__2023-11-26T02:15:06+00:00', '--job-id', '2299', '--raw', '--subdir', 'DAGS_FOLDER/example_Dag.py', '--cfg-path', '/tmp/tmp9yagh2n9']
[2025-04-14T21:14:34.566+0000] {standard_task_runner.py:85} INFO - Job 2299: Subtask task_id_example3
[2025-04-14T21:14:34.757+0000] {task_command.py:415} INFO - Running <TaskInstance: dag_id_example.task_id_example3 scheduled__2023-11-26T02:15:06+00:00 [running]> on host 018b6bcbe942
[2025-04-14T21:14:35.017+0000] {local_task_job_runner.py:115} ERROR - Received SIGTERM. Terminating subprocesses
[2025-04-14T21:14:35.027+0000] {process_utils.py:131} INFO - Sending 15 to group 2489. PIDs of all processes in the group: [2489]
[2025-04-14T21:14:35.028+0000] {process_utils.py:86} INFO - Sending the signal 15 to group 2489
[2025-04-14T21:14:35.054+0000] {taskinstance.py:1630} ERROR - Received SIGTERM. Terminating subprocesses.
[2025-04-14T21:14:35.115+0000] {taskinstance.py:1935} ERROR - Task failed with exception
Traceback (most recent call last):
  File "/home/airflow/.local/lib/python3.8/site-packages/airflow/models/taskinstance.py", line 1516, in _run_raw_task
    self._execute_task_with_callbacks(context, test_mode, session=session)
  File "/home/airflow/.local/lib/python3.8/site-packages/airflow/models/taskinstance.py", line 1649, in _execute_task_with_callbacks
    RenderedTaskInstanceFields.write(rtif)
  File "/home/airflow/.local/lib/python3.8/site-packages/airflow/utils/session.py", line 77, in wrapper
    return func(*args, session=session, **kwargs)
  File "/home/airflow/.local/lib/python3.8/site-packages/airflow/utils/retries.py", line 91, in wrapped_function
    for attempt in run_with_db_retries(max_retries=retries, logger=logger, **retry_kwargs):
  File "/home/airflow/.local/lib/python3.8/site-packages/tenacity/__init__.py", line 347, in __iter__
    do = self.iter(retry_state=retry_state)
  File "/home/airflow/.local/lib/python3.8/site-packages/tenacity/__init__.py", line 314, in iter
    return fut.result()
  File "/usr/local/lib/python3.8/concurrent/futures/_base.py", line 437, in result
    return self.__get_result()
  File "/usr/local/lib/python3.8/concurrent/futures/_base.py", line 389, in __get_result
    raise self._exception
  File "/home/airflow/.local/lib/python3.8/site-packages/airflow/utils/retries.py", line 100, in wrapped_function
    return func(*args, **kwargs)
  File "/home/airflow/.local/lib/python3.8/site-packages/airflow/models/renderedtifields.py", line 182, in write
    session.merge(self)
  File "/home/airflow/.local/lib/python3.8/site-packages/sqlalchemy/orm/session.py", line 3056, in merge
    return self._merge(
  File "/home/airflow/.local/lib/python3.8/site-packages/sqlalchemy/orm/session.py", line 3136, in _merge
    merged = self.get(
  File "/home/airflow/.local/lib/python3.8/site-packages/sqlalchemy/orm/session.py", line 2853, in get
    return self._get_impl(
  File "/home/airflow/.local/lib/python3.8/site-packages/sqlalchemy/orm/session.py", line 2975, in _get_impl
    return db_load_fn(
  File "/home/airflow/.local/lib/python3.8/site-packages/sqlalchemy/orm/loading.py", line 530, in load_on_pk_identity
    session.execute(
  File "/home/airflow/.local/lib/python3.8/site-packages/sqlalchemy/orm/session.py", line 1716, in execute
    conn = self._connection_for_bind(bind)
  File "/home/airflow/.local/lib/python3.8/site-packages/sqlalchemy/orm/session.py", line 1555, in _connection_for_bind
    return self._transaction._connection_for_bind(
  File "/home/airflow/.local/lib/python3.8/site-packages/sqlalchemy/orm/session.py", line 786, in _connection_for_bind
    self.session.dispatch.after_begin(self.session, self, conn)
  File "/home/airflow/.local/lib/python3.8/site-packages/sqlalchemy/event/attr.py", line 246, in __call__
    for fn in self.parent_listeners:
  File "/home/airflow/.local/lib/python3.8/site-packages/airflow/models/taskinstance.py", line 1632, in signal_handler
    raise AirflowException("Task received SIGTERM signal")
airflow.exceptions.AirflowException: Task received SIGTERM signal
[2025-04-14T21:14:35.264+0000] {taskinstance.py:1398} INFO - Marking task as FAILED. dag_id=dag_id_example, task_id=task_id_example3, execution_date=20231126T021506, start_date=20250414T211434, end_date=20250414T211435
[2025-04-14T21:14:35.313+0000] {standard_task_runner.py:104} ERROR - Failed to execute job 2299 for task task_id_example3 (Task received SIGTERM signal; 2489)
[2025-04-14T21:14:35.347+0000] {process_utils.py:79} INFO - Process psutil.Process(pid=2489, status='terminated', exitcode=1, started='21:14:34') (2489) terminated with exit code 1
[2025-04-14T21:14:35.348+0000] {local_task_job_runner.py:228} INFO - Task exited with return code 143
[2025-04-14T21:14:37.234+0000] {taskinstance.py:2776} INFO - 0 downstream tasks scheduled from follow-on schedule check
